<mujoco model="T1">
    <compiler angle="radian" meshdir="meshes/" />
    <size njmax="500" nconmax="100" />
    <asset>
        <texture type="skybox" builtin="gradient" rgb1="0.3 0.5 0.7" rgb2="0 0 0" width="512" height="512"/>
        <texture name="texplane" type="2d" builtin="checker" rgb1=".2 .3 .4" rgb2=".1 0.15 0.2" width="512" height="512" mark="cross" markrgb=".8 .8 .8"/>
        <material name="matplane" reflectance="0.3" texture="texplane" texrepeat="1 1" texuniform="true"/>
        <mesh name="Trunk" file="Trunk.STL" />
        <mesh name="H1" file="H1.STL" />
        <mesh name="H2" file="H2.STL" />
        <mesh name="AL1" file="AL1.STL" />
        <mesh name="AL2" file="AL2.STL" />
        <mesh name="AL3" file="AL3.STL" />
        <mesh name="left_hand_link" file="left_hand_link.STL" />
        <mesh name="AR1" file="AR1.STL" />
        <mesh name="AR2" file="AR2.STL" />
        <mesh name="AR3" file="AR3.STL" />
        <mesh name="right_hand_link" file="right_hand_link.STL" />
        <mesh name="Waist" file="Waist.STL" />
        <mesh name="Hip_Pitch_Left" file="Hip_Pitch_Left.STL" />
        <mesh name="Hip_Roll_Left" file="Hip_Roll_Left.STL" />
        <mesh name="Hip_Yaw_Left" file="Hip_Yaw_Left.STL" />
        <mesh name="Shank_Left" file="Shank_Left.STL" />
        <mesh name="Ankle_Cross_Left" file="Ankle_Cross_Left.STL" />
        <mesh name="left_foot_link" file="left_foot_link.STL" />
        <mesh name="Hip_Pitch_Right" file="Hip_Pitch_Right.STL" />
        <mesh name="Hip_Roll_Right" file="Hip_Roll_Right.STL" />
        <mesh name="Hip_Yaw_Right" file="Hip_Yaw_Right.STL" />
        <mesh name="Shank_Right" file="Shank_Right.STL" />
        <mesh name="Ankle_Cross_Right" file="Ankle_Cross_Right.STL" />
        <mesh name="right_foot_link" file="right_foot_link.STL" />
    </asset>
    <worldbody>
        <light directional="true" diffuse=".4 .4 .4" specular="0.1 0.1 0.1" pos="0 0 5.0" dir="0 0 -1" castshadow="false" />
        <light directional="true" diffuse=".6 .6 .6" specular="0.2 0.2 0.2" pos="0 0 4" dir="0 0 -1" />
        <geom name="ground" type="plane" pos="0 0 0" size="0 0 1" material="matplane" condim="1"/>
        <body name="Trunk" pos="0 0 0.7">
            <inertial pos="0.0551365 -1.42e-06 0.10506" mass="11.7" fullinertia="0.0915 0.0767 0.0556 -4.25e-07 0.000646 5.82e-07" />
            <site name='imu' size='0.01' pos='0.0 0.0 0.0' />
            <joint type="free" />
            <geom type="mesh" contype="0" conaffinity="0" group="1" rgba="0.76 0.76 0.76 0.2" mesh="Trunk" />
            <geom size="0.075 0.1 0.15" pos="0.06 0 0.12" type="box" group="0" />
            
            <geom pos="0.0625 0 0.243" type="mesh" contype="0" conaffinity="0" group="1" rgba="0.4 0.4 0.4 0.3" mesh="H1" />
            <geom pos="0.0625 0 0.30485" type="mesh" contype="0" conaffinity="0" group="1" rgba="0.4 0.4 0.4 0.3" mesh="H2" />
            
            <body name="AL1" pos="0.0575 0.1063 0.219" euler="0 0.2 0">
                <inertial pos="-0.000677 0.044974 0" mass="0.53" fullinertia="0.001293 0.000293 0.001367 -0.000017 0 0" />
                <joint name="Left_Shoulder_Pitch" pos="0 0 0" axis="0 1 0" limited="true" range="-3.31 1.22" />
                <geom type="mesh" contype="0" conaffinity="0" group="1" rgba="0.76 0.76 0.76 0.2" mesh="AL1" />
                <geom type="capsule" size="0.04 0.05" pos="0 0.02 0" euler="1.5708 0 0" group="0" />
                <body name="AL2" pos="0 0.047 0" euler="-1.35 0 0">
                    <inertial pos="0.003862 0.037976 0" mass="0.160" fullinertia="0.000345 0.000177 0.000401 0.000008 0 0" />
                    <joint name="Left_Shoulder_Roll" pos="0 0 0" axis="1 0 0" limited="true" range="-1.74 1.57" />
                    <geom type="mesh" contype="0" conaffinity="0" group="1" rgba="0.4 0.4 0.4 0.3" mesh="AL2" />
                    <geom type="capsule" size="0.03 0.04" pos="0 0.03 0" euler="1.5708 0 0" group="0" />
                    <body name="AL3" pos="0.00025 0.0605 0">
                        <inertial pos="0 0.085353 -0.000099" mass="1.02" fullinertia="0.012869 0.000621 0.012798 0 0 -0.000024" />
                        <joint name="Left_Elbow_Pitch" pos="0 0 0" axis="0 1 0" limited="true" range="-2.27 2.27" />
                        <geom type="mesh" contype="0" conaffinity="0" group="1" rgba="0.4 0.4 0.4 0.3" mesh="AL3" />
                        <geom type="capsule" size="0.03 0.07" pos="0 0.07 0" euler="1.5708 0 0" group="0" />
                        <body name="left_hand_link" pos="0 0.1471 0" euler="0 0 -0.5">
                            <inertial pos="-0.000108 0.109573 0.000591" mass="0.327" fullinertia="0.008159 0.000215 0.008131 -0.000003 0 0.000017" />
                            <joint name="Left_Elbow_Yaw" pos="0 0 0" axis="0 0 1" limited="true" range="-2.44 0" />
                            <geom type="mesh" contype="0" conaffinity="0" group="1" rgba="0.4 0.4 0.4 0.3" mesh="left_hand_link" />
                            <geom type="box" size="0.02 0.05 0.02" pos="0 0.1 0" group="0" />
                        </body>
                    </body>
                </body>
            </body>
            
            <body name="AR1" pos="0.0575 -0.1063 0.219" euler="0 0.2 0">
                <inertial pos="-0.000677 -0.044974 0" mass="0.53" fullinertia="0.001293 0.000293 0.001367 -0.000017 0 0" />
                <joint name="Right_Shoulder_Pitch" pos="0 0 0" axis="0 1 0" limited="true" range="-3.31 1.22" />
                <geom type="mesh" contype="0" conaffinity="0" group="1" rgba="0.76 0.76 0.76 0.2" mesh="AR1" />
                <geom type="capsule" size="0.04 0.05" pos="0 -0.02 0" euler="1.5708 0 0" group="0" />
                <body name="AR2" pos="0 -0.047 0" euler="1.35 0 0">
                    <inertial pos="0.003862 -0.037976 0" mass="0.160" fullinertia="0.000345 0.000177 0.000401 -0.000008 0 0" />
                    <joint name="Right_Shoulder_Roll" pos="0 0 0" axis="1 0 0" limited="true" range="-1.57 1.74" />
                    <geom type="mesh" contype="0" conaffinity="0" group="1" rgba="0.4 0.4 0.4 0.3" mesh="AR2" />
                    <geom type="capsule" size="0.03 0.04" pos="0 -0.03 0" euler="1.5708 0 0" group="0" />
                    <body name="AR3" pos="0.00025 -0.0605 0">
                        <inertial pos="0 -0.085353 -0.000099" mass="1.02" fullinertia="0.012869 0.000621 0.012798 0 0 0.000024" />
                        <joint name="Right_Elbow_Pitch" pos="0 0 0" axis="0 1 0" limited="true" range="-2.27 2.27" />
                        <geom type="mesh" contype="0" conaffinity="0" group="1" rgba="0.4 0.4 0.4 0.3" mesh="AR3" />
                        <geom type="capsule" size="0.03 0.07" pos="0 -0.07 0" euler="1.5708 0 0" group="0" />
                        <body name="right_hand_link" pos="0 -0.1471 0" euler="0 0 0.5">
                            <inertial pos="-0.000108 -0.109573 0.000591" mass="0.327" fullinertia="0.008159 0.000215 0.008131 0.000003 0 -0.000017" />
                            <joint name="Right_Elbow_Yaw" pos="0 0 0" axis="0 0 1" limited="true" range="0 2.44" />
                            <geom type="mesh" contype="0" conaffinity="0" group="1" rgba="0.4 0.4 0.4 0.3" mesh="right_hand_link" />
                            <geom type="box" size="0.02 0.05 0.02" pos="0 -0.1 0" group="0" />
                        </body>
                    </body>
                </body>
            </body>

            <body name="Waist" pos="0.0625 0 -0.1155">
                <inertial pos="0.002284 0.000003 0.007301" mass="2.581" fullinertia="0.005289 0.005299 0.004821 0 0.000207 0.000001" />
                <joint name="Waist" pos="0 0 0" axis="0 0 1" limited="true" range="-1.57 1.57" />
                <geom type="mesh" contype="0" conaffinity="0" group="1" rgba="0.4 0.4 0.4 0.3" mesh="Waist" />

                <body name="Hip_Pitch_Left" pos="0 0.106 0">
                    <inertial pos="0.000534 -0.007296 -0.018083" mass="1.021" fullinertia="0.001805 0.001421 0.001292 0.000006 -0.000015 0.000080" />
                    <joint name="Left_Hip_Pitch" pos="0 0 0" axis="0 1 0" limited="true" range="-1.8 1.57" />
                    <geom type="mesh" contype="0" conaffinity="0" group="1" rgba="0.76 0.76 0.76 0.2" mesh="Hip_Pitch_Left" />
                    <body name="Hip_Roll_Left" pos="0 0 -0.02">
                        <inertial pos="0.001101 0.000024 -0.053750" mass="0.385" fullinertia="0.001517 0.001743 0.000515 0 0.000017 0" />
                        <joint name="Left_Hip_Roll" pos="0 0 0" axis="1 0 0" limited="true" range="-0.3 1.57" />
                        <geom type="mesh" contype="0" conaffinity="0" group="1" rgba="0.4 0.4 0.4 0.3" mesh="Hip_Roll_Left" />
                        <body name="Hip_Yaw_Left" pos="0 0 -0.081854">
                            <inertial pos="-0.007233 0.000206 -0.089184" mass="2.166" fullinertia="0.025108 0.025733 0.002787 -0.000007 0.002094 -0.000050" />
                            <joint name="Left_Hip_Yaw" pos="0 0 0" axis="0 0 1" limited="true" range="-1 1" />
                            <geom type="mesh" contype="0" conaffinity="0" group="1" rgba="0.4 0.4 0.4 0.3" mesh="Hip_Yaw_Left" />
                            <geom size="0.05 0.08" type="cylinder" group="0" />
                            <body name="Shank_Left" pos="-0.014 0 -0.134">
                                <inertial pos="-0.006012 0.000259 -0.124318" mass="1.73" fullinertia="0.034618 0.034539 0.001934 0.000011 0.001561 0.000197" />
                                <joint name="Left_Knee_Pitch" pos="0 0 0" axis="0 1 0" limited="true" range="0 2.34" />
                                <geom type="mesh" contype="0" conaffinity="0" group="1" rgba="0.4 0.4 0.4 0.3" mesh="Shank_Left" />
                                <geom size="0.05 0.075" pos="0 0 -0.12" type="cylinder" group="0" />
                                <body name="Ankle_Cross_Left" pos="0 0 -0.28">
                                    <inertial pos="-0.003722 0 -0.007981" mass="0.073" fullinertia="0.000012 0.000029 0.000025 0 0.000003 0" />
                                    <joint name="Left_Ankle_Pitch" pos="0 0 0" axis="0 1 0" limited="true" range="-0.87 0.35" />
                                    <geom type="mesh" contype="0" conaffinity="0" group="1" rgba="0.4 0.4 0.4 0.3" mesh="Ankle_Cross_Left" />
                                    <body name="left_foot_link" pos="0 0.00025 -0.012">
                                        <inertial pos="-0.000249 0 -0.009140" mass="0.685" fullinertia="0.001738 0.002385 0.002671 0 -0.000147 0" />
                                        <joint name="Left_Ankle_Roll" pos="0 0 0" axis="1 0 0" limited="true" range="-0.44 0.44" />
                                        <geom type="mesh" contype="0" conaffinity="0" group="1" rgba="0.4 0.4 0.4 0.3" mesh="left_foot_link" />
                                        <geom size="0.1115 0.05 0.015" pos="0.01 0 -0.015" type="box" group="0" />
                                    </body>
                                </body>
                            </body>
                        </body>
                    </body>
                </body>

                <body name="Hip_Pitch_Right" pos="0 -0.106 0">
                    <inertial pos="0.000534 0.007514 -0.018082" mass="1.021" fullinertia="0.001805 0.001421 0.001292 -0.000008 -0.000015 -0.000085" />
                    <joint name="Right_Hip_Pitch" pos="0 0 0" axis="0 1 0" limited="true" range="-1.8 1.57" />
                    <geom type="mesh" contype="0" conaffinity="0" group="1" rgba="0.76 0.76 0.76 0.2" mesh="Hip_Pitch_Right" />
                    <body name="Hip_Roll_Right" pos="0 0 -0.02">
                        <inertial pos="0.001099 0.000024 -0.053748" mass="0.385" fullinertia="0.001517 0.001743 0.000515 0 0.000017 0" />
                        <joint name="Right_Hip_Roll" pos="0 0 0" axis="1 0 0" limited="true" range="-1.57 0.3" />
                        <geom type="mesh" contype="0" conaffinity="0" group="1" rgba="0.4 0.4 0.4 0.3" mesh="Hip_Roll_Right" />
                        <body name="Hip_Yaw_Right" pos="0 0 -0.081854">
                            <inertial pos="-0.007191 -0.000149 -0.089220" mass="2.17" fullinertia="0.025137 0.025762 0.002787 0.000006 0.002086 0.000044" />
                            <joint name="Right_Hip_Yaw" pos="0 0 0" axis="0 0 1" limited="true" range="-1 1" />
                            <geom type="mesh" contype="0" conaffinity="0" group="1" rgba="0.4 0.4 0.4 0.3" mesh="Hip_Yaw_Right" />
                            <geom size="0.05 0.08" type="cylinder" group="0" />
                            <body name="Shank_Right" pos="-0.014 0 -0.134">
                                <inertial pos="-0.005741 -0.000541 -0.122602" mass="1.79" fullinertia="0.035098 0.034958 0.002039 -0.000009 0.001554 -0.000086" />
                                <joint name="Right_Knee_Pitch" pos="0 0 0" axis="0 1 0" limited="true" range="0 2.34" />
                                <geom type="mesh" contype="0" conaffinity="0" group="1" rgba="0.4 0.4 0.4 0.3" mesh="Shank_Right" />
                                <geom size="0.05 0.075" pos="0 0 -0.12" type="cylinder" group="0" />
                                <body name="Ankle_Cross_Right" pos="0 0 -0.28">
                                    <inertial pos="-0.003722 0 -0.007981" mass="0.073" fullinertia="0.000012 0.000029 0.000025 0 0.000003 0" />
                                    <joint name="Right_Ankle_Pitch" pos="0 0 0" axis="0 1 0" limited="true" range="-0.87 0.35" />
                                    <geom type="mesh" contype="0" conaffinity="0" group="1" rgba="0.4 0.4 0.4 0.3" mesh="Ankle_Cross_Right" />
                                    <body name="right_foot_link" pos="0 -0.00025 -0.012">
                                        <inertial pos="-0.000248 0 -0.009140" mass="0.685" fullinertia="0.001738 0.002385 0.002671 0 -0.000147 0" />
                                        <joint name="Right_Ankle_Roll" pos="0 0 0" axis="1 0 0" limited="true" range="-0.44 0.44" />
                                        <geom type="mesh" contype="0" conaffinity="0" group="1" rgba="0.4 0.4 0.4 0.3" mesh="right_foot_link" />
                                        <geom size="0.1115 0.05 0.015" pos="0.01 0 -0.015" type="box" group="0" />
                                    </body>
                                </body>
                            </body>
                        </body>
                    </body>
                </body>
            </body>
        </body>
    </worldbody>
    <actuator>
        <motor name="Left_Shoulder_Pitch" joint="Left_Shoulder_Pitch" ctrlrange="-18.0 18.0" ctrllimited="true" />
        <motor name="Left_Shoulder_Roll" joint="Left_Shoulder_Roll" ctrlrange="-18.0 18.0" ctrllimited="true" />
        <motor name="Left_Elbow_Pitch" joint="Left_Elbow_Pitch" ctrlrange="-18.0 18.0" ctrllimited="true" />
        <motor name="Left_Elbow_Yaw" joint="Left_Elbow_Yaw" ctrlrange="-18.0 18.0" ctrllimited="true" />
        <motor name="Right_Shoulder_Pitch" joint="Right_Shoulder_Pitch" ctrlrange="-18.0 18.0" ctrllimited="true" />
        <motor name="Right_Shoulder_Roll" joint="Right_Shoulder_Roll" ctrlrange="-18.0 18.0" ctrllimited="true" />
        <motor name="Right_Elbow_Pitch" joint="Right_Elbow_Pitch" ctrlrange="-18.0 18.0" ctrllimited="true" />
        <motor name="Right_Elbow_Yaw" joint="Right_Elbow_Yaw" ctrlrange="-18.0 18.0" ctrllimited="true" />
        <motor name="Waist" joint="Waist" ctrlrange="-30.0 30.0" ctrllimited="true" />
        <motor name="Left_Hip_Pitch" joint="Left_Hip_Pitch" ctrlrange="-45.0 45.0" ctrllimited="true" />
        <motor name="Left_Hip_Roll" joint="Left_Hip_Roll" ctrlrange="-30.0 30.0" ctrllimited="true" />
        <motor name="Left_Hip_Yaw" joint="Left_Hip_Yaw" ctrlrange="-30.0 30.0" ctrllimited="true" />
        <motor name="Left_Knee_Pitch" joint="Left_Knee_Pitch" ctrlrange="-60.0 60.0" ctrllimited="true" />
        <motor name="Left_Ankle_Pitch" joint="Left_Ankle_Pitch" ctrlrange="-24.0 24.0" ctrllimited="true" />
        <motor name="Left_Ankle_Roll" joint="Left_Ankle_Roll" ctrlrange="-15.0 15.0" ctrllimited="true" />
        <motor name="Right_Hip_Pitch" joint="Right_Hip_Pitch" ctrlrange="-45.0 45.0" ctrllimited="true" />
        <motor name="Right_Hip_Roll" joint="Right_Hip_Roll" ctrlrange="-30.0 30.0" ctrllimited="true" />
        <motor name="Right_Hip_Yaw" joint="Right_Hip_Yaw" ctrlrange="-30.0 30.0" ctrllimited="true" />
        <motor name="Right_Knee_Pitch" joint="Right_Knee_Pitch" ctrlrange="-60.0 60.0" ctrllimited="true" />
        <motor name="Right_Ankle_Pitch" joint="Right_Ankle_Pitch" ctrlrange="-24.0 24.0" ctrllimited="true" />
        <motor name="Right_Ankle_Roll" joint="Right_Ankle_Roll" ctrlrange="-15.0 15.0" ctrllimited="true" />
    </actuator>
    <sensor>
        <framequat name="orientation" objtype="site" noise="0.001" objname="imu" />
        <gyro name="angular-velocity" site="imu" noise="0.005" />
        <velocimeter name="linear-velocity" site="imu"/>
    </sensor>
</mujoco>